2024-05-15 21:19:04,420 : INFO : Start of Training
2024-05-15 21:19:04,420 : INFO : Run_id:2024-05-15_211904_eb2c8d8ff45e25ca
2024-05-15 21:19:04,421 : ERROR : Unsuccessful End of Training
Traceback (most recent call last):
  File "C:\Users\UKASHI\PycharmProjects\employee_attrition\apps\training\train_model.py", line 82, in training_model
    self.loadValidate.validate_train_set()
AttributeError: 'NoneType' object has no attribute 'validate_train_set'
